<?xml version="1.0"?>
<robot name="tiltplat">
	
  <material name="blue">
    <color rgba="0 0 0.8 1"/>
  </material>
	
  <material name="blue_glass">
    <color rgba="0.8 0.8 1 0.8"/>
  </material>	

  <material name="white">
    <color rgba="1 1 1 1"/>
  </material>

  <material name="white_glass">
    <color rgba="1 1 1 0.5"/>
  </material>
	
  <material name="handrail">
    <color rgba="1 1 1 0.5"/>
  </material>

  <material name="post">
    <color rgba="0 0 0 0.7"/>
  </material>
	
  <link name="platform">
    <visual>
	  <material name="blue_glass"/>
      <geometry>
        <cylinder length="0.1" radius="1.5"/>
      </geometry>
    </visual>
	<collision>
	  <geometry>
        <cylinder length="0.1" radius="1.5"/>
      </geometry>
	</collision>
	<inertial>
      <mass value="50"/>
      <inertia ixx="28.1354167" ixy="0.0" ixz="0.0" iyy="28.1354167" iyz="0.0" izz="9.375"/>
    </inertial>
  </link>
  
  <link name="ball">
    <!--<visual>
	  <material name="white"/>
      <geometry>
        <sphere radius="0.1"/>
      </geometry>
	  <origin xyz="0 0 0"/>
    </visual>-->
	<inertial>
      <mass value="0.1"/>
      <inertia ixx="0.0004" ixy="0.0" ixz="0.0" iyy="0.0004" iyz="0.0" izz="0.0004"/>
    </inertial>
  </link>

  <joint name="jointX" type="revolute">
    <parent link="ball"/>
    <child link="platform"/>
    <origin rpy="0 0 0" xyz="0 0 0"/>
    <axis xyz="1 0 0"/>
    <limit effort="50" lower="-0.25" upper="0.25" velocity="1.0"/>
    <dynamics damping="3.0" friction="0"/>
  </joint>

  <link name="tube">
    <visual>
      <geometry>
        <cylinder length="0.6" radius="0.08"/>
      </geometry>
	  <origin rpy="0 0 0" xyz="0 0 0"/>
    </visual>
	<inertial>
      <mass value="50"/>
      <inertia ixx="1.0" ixy="0.0" ixz="0.0" iyy="1.0" iyz="0.0" izz="1.0"/>
    </inertial>
  </link>
  
  <joint name="jointY" type="revolute">
    <parent link="tube"/>
    <child link="ball"/>
    <origin rpy="0 0 0" xyz="0 0 0.325"/>
    <axis xyz="0 1 0"/>
    <limit effort="50" lower="-0.25" upper="0.25" velocity="1.0"/>
    <dynamics damping="3.0" friction="0"/>
  </joint>
  


  
  <link name="base">
    <visual>
      <geometry>
        <box size="1 1 0.2"/>
      </geometry>
	  <origin xyz="0 0 0"/>
    </visual>
	<collision>
	 <geometry>
        <box size="1 1 0.2"/>
      </geometry>
	  <origin xyz="0 0 0"/>
	</collision>
	<inertial>
      <mass value="10000"/>
      <inertia ixx="866.666667" ixy="0.0" ixz="0.0" iyy="1666.66667" iyz="0.0" izz="866.666667"/>
    </inertial>
  </link>
  
  <joint name="baseJoint" type="fixed">
    <parent link="base"/>
    <child link="tube"/>
	<origin xyz="0 0 0.4"/>
  </joint>
	
	
  <link name="post1">
    <visual>
	  <material name="post"/>
      <geometry>
        <cylinder length="0.4" radius="0.03"/>
      </geometry>
	  <origin rpy="0 0 0" xyz="0 0 0"/>
    </visual>
	<inertial>
      <mass value="0.1"/>
      <inertia ixx="1.0" ixy="0.0" ixz="0.0" iyy="1.0" iyz="0.0" izz="1.0"/>
    </inertial>
  </link>
	
  <link name="post2">
    <visual>
	  <material name="post"/>
      <geometry>
        <cylinder length="0.4" radius="0.03"/>
      </geometry>
	  <origin rpy="0 0 0" xyz="0 0 0"/>
    </visual>
	<inertial>
      <mass value="0.1"/>
      <inertia ixx="1.0" ixy="0.0" ixz="0.0" iyy="1.0" iyz="0.0" izz="1.0"/>
    </inertial>
  </link>
	
  <link name="post3">
    <visual>
	  <material name="post"/>
      <geometry>
        <cylinder length="0.4" radius="0.03"/>
      </geometry>
	  <origin rpy="0 0 0" xyz="0 0 0"/>
    </visual>
	<inertial>
      <mass value="0.1"/>
      <inertia ixx="1.0" ixy="0.0" ixz="0.0" iyy="1.0" iyz="0.0" izz="1.0"/>
    </inertial>
  </link>
	
  <link name="post4">
    <visual>
	  <material name="post"/>
      <geometry>
        <cylinder length="0.4" radius="0.03"/>
      </geometry>
	  <origin rpy="0 0 0" xyz="0 0 0"/>
    </visual>
	<inertial>
      <mass value="0.1"/>
      <inertia ixx="1.0" ixy="0.0" ixz="0.0" iyy="1.0" iyz="0.0" izz="1.0"/>
    </inertial>
  </link>
	
  <link name="post5">
    <visual>
	  <material name="post"/>
      <geometry>
        <cylinder length="0.4" radius="0.03"/>
      </geometry>
	  <origin rpy="0 0 0" xyz="0 0 0"/>
    </visual>
	<inertial>
      <mass value="0.1"/>
      <inertia ixx="1.0" ixy="0.0" ixz="0.0" iyy="1.0" iyz="0.0" izz="1.0"/>
    </inertial>
  </link>
	
  <link name="post6">
    <visual>
	  <material name="post"/>
      <geometry>
        <cylinder length="0.4" radius="0.03"/>
      </geometry>
	  <origin rpy="0 0 0" xyz="0 0 0"/>
    </visual>
	<inertial>
      <mass value="0.1"/>
      <inertia ixx="1.0" ixy="0.0" ixz="0.0" iyy="1.0" iyz="0.0" izz="1.0"/>
    </inertial>
  </link>
	
  <joint name="post1joint" type="fixed">
    <parent link="platform"/>
    <child link="post1"/>
	<origin xyz="1.42 0 0.25"/>
  </joint>
  
  <joint name="post2joint" type="fixed">
    <parent link="platform"/>
    <child link="post2"/>
	<origin xyz="0.71 1.22975 0.25"/>
  </joint>
	
  <joint name="post3joint" type="fixed">
    <parent link="platform"/>
    <child link="post3"/>
	<origin xyz="-0.71 1.22975 0.25"/>
  </joint>
  
  <joint name="post4joint" type="fixed">
    <parent link="platform"/>
    <child link="post4"/>
	<origin xyz="-1.42 0 0.25"/>
  </joint>
	
  <joint name="post5joint" type="fixed">
    <parent link="platform"/>
    <child link="post5"/>
	<origin xyz="-0.71 -1.22975 0.25"/>
  </joint>
  
  <joint name="post6joint" type="fixed">
    <parent link="platform"/>
    <child link="post6"/>
	<origin xyz="0.71 -1.22975 0.25"/>
  </joint>
	
  <link name="handrail1">
    <visual>
	  <material name="handrail"/>
      <geometry>
        <box size="1.42 0.05 0.05"/>
      </geometry>
	  <origin rpy="0 0 0" xyz="0.71 0 0"/>
    </visual>
	<collision>
      <geometry>
        <box size="1.42 0.05 0.05"/>
      </geometry>
	  <origin rpy="0 0 0" xyz="0.71 0 0"/>
    </collision>
	<inertial>
      <mass value="0.1"/>
      <inertia ixx="1.0" ixy="0.0" ixz="0.0" iyy="1.0" iyz="0.0" izz="1.0"/>
    </inertial>
  </link>

  <link name="handrail2">
    <visual>
	  <material name="handrail"/>
      <geometry>
        <box size="1.42 0.05 0.05"/>
      </geometry>
	  <origin rpy="0 0 0" xyz="0.71 0 0"/>
    </visual>
	<collision>
      <geometry>
        <box size="1.42 0.05 0.05"/>
      </geometry>
	  <origin rpy="0 0 0" xyz="0.71 0 0"/>
    </collision>
	<inertial>
      <mass value="0.1"/>
      <inertia ixx="1.0" ixy="0.0" ixz="0.0" iyy="1.0" iyz="0.0" izz="1.0"/>
    </inertial>
  </link>
	
  <link name="handrail3">
    <visual>
	  <material name="handrail"/>
      <geometry>
        <box size="1.42 0.05 0.05"/>
      </geometry>
	  <origin rpy="0 0 0" xyz="0.71 0 0"/>
    </visual>
	<collision>
      <geometry>
        <box size="1.42 0.05 0.05"/>
      </geometry>
	  <origin rpy="0 0 0" xyz="0.71 0 0"/>
    </collision>
	<inertial>
      <mass value="0.1"/>
      <inertia ixx="1.0" ixy="0.0" ixz="0.0" iyy="1.0" iyz="0.0" izz="1.0"/>
    </inertial>
  </link>
	
  <link name="handrail4">
    <visual>
	  <material name="handrail"/>
      <geometry>
        <box size="1.42 0.05 0.05"/>
      </geometry>
	  <origin rpy="0 0 0" xyz="0.71 0 0"/>
    </visual>
	<collision>
      <geometry>
        <box size="1.42 0.05 0.05"/>
      </geometry>
	  <origin rpy="0 0 0" xyz="0.71 0 0"/>
    </collision>
	<inertial>
      <mass value="0.1"/>
      <inertia ixx="1.0" ixy="0.0" ixz="0.0" iyy="1.0" iyz="0.0" izz="1.0"/>
    </inertial>
  </link>
	
  <link name="handrail5">
    <visual>
	  <material name="handrail"/>
      <geometry>
        <box size="1.42 0.05 0.05"/>
      </geometry>
	  <origin rpy="0 0 0" xyz="0.71 0 0"/>
    </visual>
	<collision>
      <geometry>
        <box size="1.42 0.05 0.05"/>
      </geometry>
	  <origin rpy="0 0 0" xyz="0.71 0 0"/>
    </collision>
	<inertial>
      <mass value="0.1"/>
      <inertia ixx="1.0" ixy="0.0" ixz="0.0" iyy="1.0" iyz="0.0" izz="1.0"/>
    </inertial>
  </link>
	
  <link name="handrail6">
    <visual>
	  <material name="handrail"/>
      <geometry>
        <box size="1.42 0.05 0.05"/>
      </geometry>
	  <origin rpy="0 0 0" xyz="0.71 0 0"/>
    </visual>
	<collision>
      <geometry>
        <box size="1.42 0.05 0.05"/>
      </geometry>
	  <origin rpy="0 0 0" xyz="0.71 0 0"/>
    </collision>
	<inertial>
      <mass value="0.1"/>
      <inertia ixx="1.0" ixy="0.0" ixz="0.0" iyy="1.0" iyz="0.0" izz="1.0"/>
    </inertial>
  </link>
	
  <joint name="handrail1joint" type="fixed">
    <parent link="post1"/>
    <child link="handrail1"/>
	<origin rpy="0 0 2.094395" xyz="0 0  0.15"/>
  </joint>
	
  <joint name="handrail2joint" type="fixed">
    <parent link="post3"/>
    <child link="handrail2"/>
	<origin rpy="0 0 0" xyz="0 0  0.15"/>
  </joint>
	
  <joint name="handrail3joint" type="fixed">
    <parent link="post4"/>
    <child link="handrail3"/>
	<origin rpy="0 0 1.04719755" xyz="0 0  0.15"/>
  </joint>
	
  <joint name="handrail4joint" type="fixed">
    <parent link="post5"/>
    <child link="handrail4"/>
	<origin rpy="0 0 2.094395" xyz="0 0  0.15"/>
  </joint>
	
  <joint name="handrail5joint" type="fixed">
    <parent link="post5"/>
    <child link="handrail5"/>
	<origin rpy="0 0 0" xyz="0 0  0.15"/>
  </joint>
	
  <joint name="handrail6joint" type="fixed">
    <parent link="post6"/>
    <child link="handrail6"/>
	<origin rpy="0 0 1.04719755" xyz="0 0  0.15"/>
  </joint>


</robot>